<?xml version="1.0"?>
<robot name="backhoe_ZX55UR-5B">

  <!-- 1. Turret -->
  <link name="turret">
    <inertial>
      <origin xyz="0 0 0.1"/>
      <mass value="3000.0"/>
      <inertia ixx="5" iyy="5" izz="5" ixy="0" ixz="0" iyz="0"/>
    </inertial>
    <visual>
      <geometry>
        <box size="1.6 1.6 0.2"/>
      </geometry>
      <origin xyz="0 0 0.1"/>
      <material name="red">
        <color rgba="1 0 0 1"/>
      </material>
    </visual>
    <collision>
      <geometry>
        <box size="1.6 1.6 0.2"/>
      </geometry>
      <origin xyz="0 0 0.1"/>
    </collision>
  </link>

  <!-- 2.1 Boom Segment 1 (vertikal) -->
  <link name="boom_lower">
    <inertial>
      <origin xyz="0 0 0.9"/>
      <mass value="200"/>
      <inertia ixx="2" iyy="2" izz="1" ixy="0" ixz="0" iyz="0"/>
    </inertial>
    <visual>
      <geometry>
        <box size="0.5 0.5 1.8"/>
      </geometry>
      <origin xyz="0 0 0.9"/>
      <material name="blue">
        <color rgba="0 0 1 1"/>
      </material>
    </visual>
    <collision>
      <geometry>
        <box size="0.5 0.5 1.8"/>
      </geometry>
      <origin xyz="0 0 0.9"/>
    </collision>
  </link>

  <!-- 2.2 Boom Segment 2 (leicht nach vorne geneigt) -->
  <link name="boom_upper">
    <inertial>
      <origin xyz="0 0 0.9"/>
      <mass value="182"/>
      <inertia ixx="1" iyy="1" izz="0.5" ixy="0" ixz="0" iyz="0"/>
    </inertial>
    <visual>
      <geometry>
        <box size="0.4 0.4 1.8"/>
      </geometry>
      <origin xyz="0.5 0.0 0.9" rpy="0.0 0.4 0.0"/>
      <material name="blue">
        <color rgba="0 0 1 1"/>
      </material>
    </visual>
    <collision>
      <geometry>
        <box size="0.5 0.5 1.8"/>
      </geometry>
      <origin xyz="0 0 0.9" rpy="0 0 0.3"/>
    </collision>
  </link>

  <!-- Boom-Teil 1 wird am Turret montiert -->
  <joint name="turret_to_boom_lower" type="revolute">
    <parent link="turret"/>
    <child link="boom_lower"/>
    <origin xyz="0 0 0.5" rpy="0 0 0"/>
    <axis xyz="0 1 0"/>
    <limit lower="-0.4" upper="1.2" effort="1000" velocity="1.5"/>
  </joint>

  <!-- Boom-Teil 2 ist fest mit Teil 1 verbunden -->
  <joint name="boom_fixed_joint" type="fixed">
    <parent link="boom_lower"/>
    <child link="boom_upper"/>
    <origin xyz="0 0 1.8" rpy="0 0 0"/>
  </joint>

  <!-- 3. Stick -->
  <link name="stick">
    <inertial>
      <origin xyz="0 0 0.8"/>
      <mass value="156.0"/>
      <inertia ixx="2" iyy="2" izz="0.8" ixy="0" ixz="0" iyz="0"/>
    </inertial>
    <visual>
      <geometry>
        <box size="0.3 0.3 1.6"/>
      </geometry>
      <origin xyz="0 0 0.8"/>
      <material name="yellow">
        <color rgba="1 1 0 1"/>
      </material>
    </visual>
    <collision>
      <geometry>
        <box size="0.3 0.3 1.6"/>
      </geometry>
      <origin xyz="0 0 0.8"/>
    </collision>
  </link>

  <joint name="boom_to_stick" type="revolute">
    <parent link="boom_upper"/>
    <child link="stick"/>
    <origin xyz="0 0 1.8" rpy="0 0 0"/>
    <axis xyz="0 1 0"/>
    <limit lower="-1.57" upper="1.57" effort="800" velocity="3.2"/>
  </joint>

  <!-- 4. Bucket -->
  <link name="bucket">
    <inertial>
      <origin xyz="0 0 0.2"/>
      <mass value="100.0"/>
      <inertia ixx="1" iyy="1" izz="0.5" ixy="0" ixz="0" iyz="0"/>
    </inertial>
    <visual>
      <geometry>
        <box size="0.5 1.0 0.4"/>
      </geometry>
      <origin xyz="0 0 0.2"/>
      <material name="green">
        <color rgba="0 1 0 1"/>
      </material>
    </visual>
    <collision>
      <geometry>
        <box size="0.5 1.0 0.4"/>
      </geometry>
      <origin xyz="0 0 0.2"/>
    </collision>
  </link>

  <joint name="stick_to_bucket" type="revolute">
    <parent link="stick"/>
    <child link="bucket"/>
    <origin xyz="0 0 1.6" rpy="0 0 0"/>
    <axis xyz="0 1 0"/>
    <limit lower="-1.5" upper="1.5" effort="500" velocity="1.0"/>
  </joint>

</robot>
